Workbook

Sheet Cover
B2: COSTCO WHOLESALE CORPORATION
B3: Discounted Cash Flow (DCF) Valuation Model
B4: NASDAQ: COST | Consumer Staples — Warehouse Clubs & Retail
B5: All figures in US$ millions unless otherwise noted
B7: VALUATION SUMMARY
B8: Valuation date | C8: =Assumptions!C6 -> 45900
B9: WACC | C9: =WACC!C23 -> 0.088718279
B10: Terminal growth rate (perpetuity) | C10: =Assumptions!C31 -> 0.03
B11: Enterprise value (perpetuity method) | C11: ='DCF Model'!F35 -> 122046.46
B12: Implied equity value | C12: ='DCF Model'!F38 -> 131542.46
B13: Implied value / share (perpetuity method) | C13: ='DCF Model'!F40 -> 295.73195
B14: Implied value / share (exit-multiple method) | C14: ='DCF Model'!F54 -> 592.82604
B15: Current share price | C15: =Assumptions!C7 -> 915
B16: Implied upside / (downside) — perpetuity | C16: ='DCF Model'!F42 -> -0.67679568
B17: How to read this: a conventional 5-year + terminal DCF values COST below its market price because the stock trades at a large premium. See the reverse-DCF and sensitivity tabs for the growth/multiple the market implies.
B20: CONTENTS
B21: 1. Assumptions | C21: Operating drivers, ratio assumptions, market data & terminal assumptions
B22: 2. WACC | C22: Weighted-average cost of capital build-up (CAPM)
B23: 3. DCF Model | C23: Unlevered FCF projection (split COGS/SG&A), terminal value & value/share
B24: 4. Sensitivity | C24: Value/share vs. WACC, terminal growth and exit multiple
B25: 5. Historicals | C25: Sourced FY2021–FY2025 income statement, cash flow & balance sheet
B27: COLOR & FORMAT LEGEND
B28: Blue text | C28: Hardcoded input / assumption — edit these to drive the model
B29: Black text | C29: Formula / calculated cell — do not overwrite
B30: Green text | C30: Link to another worksheet in this workbook
B31: Yellow fill | C31: Key assumption you are expected to change
B33: PRIMARY SOURCES
B34: • Costco FY2025 Q4/full-year earnings release (52 wks ended 31-Aug-2025), filed 25-Sep-2025 — income statement, balance sheet, cash flow.
B35: • Costco FY2021–FY2024 10-K filings (SEC EDGAR, CIK 0000909832) — prior-year income statement, cash flow & balance sheet detail.
B36: • Costco FY2025 10-K — debt schedule, effective tax rate, weighted-avg interest rate 2.49%.
B37: • Market data (share price ~$915, beta ~0.88) as of 10–11 Jul 2026; U.S. 10-yr Treasury ~4.55% (10-Jul-2026).
B39: Disclaimer: For illustrative/educational purposes only; not investment advice. A DCF is highly sensitive to its assumptions; outputs are estimates, not price targets. Verify all inputs against primary filings before use.

Sheet Assumptions
B2: ASSUMPTIONS & KEY DRIVERS
B3: Blue = input (edit) · Yellow fill = key lever · All $ in millions
B5: MARKET DATA & VALUATION DATE
B6: Valuation date (fiscal year-end base) | C6: =DATE(2025,8,31) -> 45900
B7: Current share price ($/share) | C7: 915
B8: Diluted shares outstanding (millions) | C8: 444.803
B10: NET CASH BRIDGE (FY2025 balance sheet)
B11: Cash & cash equivalents | C11: 14161
B12: Short-term investments | C12: 1123
B13: Less: long-term debt (excl. current portion) | C13: -5713
B14: Less: current portion of long-term debt | C14: -75
B15: Net cash / (net debt) | C15: =SUM(C11:C14) -> 9496
B17: OPERATING DRIVERS BY FORECAST YEAR
B18: Fiscal year ending August | C18: 2026E | D18: 2027E | E18: 2028E | F18: 2029E | G18: 2030E
B19: Net sales growth (YoY) | C19: 0.08 | D19: 0.075 | E19: 0.07 | F19: 0.065 | G19: 0.06
B20: Membership fee growth (YoY) | C20: 0.085 | D20: 0.08 | E20: 0.075 | F20: 0.07 | G20: 0.065
B21: Merchandise costs (% of net sales) | C21: 0.8885 | D21: 0.888 | E21: 0.8875 | F21: 0.887 | G21: 0.8865
B22: SG&A (% of total revenue) | C22: 0.0905 | D22: 0.0904 | E22: 0.0903 | F22: 0.0902 | G22: 0.0901
B24: RATIO & TAX ASSUMPTIONS
B25: Depreciation & amortization (% of revenue) | C25: 0.009
B26: Capital expenditure (% of revenue) | C26: 0.02
B27: Net working capital (% of revenue) | C27: -0.03
B28: Effective tax rate | C28: 0.25
B30: TERMINAL VALUE ASSUMPTIONS
B31: Terminal growth rate (perpetuity method) | C31: 0.03
B32: Exit EV/EBITDA multiple (exit-multiple method) | C32: 18

Sheet WACC
B2: WEIGHTED-AVERAGE COST OF CAPITAL (WACC)
B3: CAPM-based; blue = input, black = formula, green = link
B5: COST OF EQUITY (CAPM)
B6: Risk-free rate (10-yr U.S. Treasury) | C6: 0.0455
B7: Equity risk premium | C7: 0.05
B8: Beta (levered) | C8: 0.88
B9: Cost of equity = Rf + Beta × ERP | C9: =C6+C8*C7 -> 0.0895
B11: COST OF DEBT
B12: Pre-tax cost of debt | C12: 0.045
B13: Effective tax rate | C13: =Assumptions!C28 -> 0.25
B14: After-tax cost of debt = Kd × (1 − tax) | C14: =C12*(1-C13) -> 0.03375
B16: CAPITAL STRUCTURE (market values, $mm)
B17: Market value of equity (price × shares) | C17: =Assumptions!C7*Assumptions!C8 -> 406994.74
B18: Total debt (book value, FY2025) | C18: =-(Assumptions!C13+Assumptions!C14) -> 5788
B19: Total capitalization | C19: =C17+C18 -> 412782.74
B20: Weight of equity | C20: =C17/C19 -> 0.9859781
B21: Weight of debt | C21: =C18/C19 -> 0.014021904
B23: WACC = We×Ke + Wd×Kd(1−t) | C23: =C20*C9+C21*C14 -> 0.088718279

Sheet Historicals
B2: HISTORICAL FINANCIALS (as reported)
B3: Source: Costco FY2021–FY2025 earnings releases & 10-K filings (SEC EDGAR) · $ in millions
B5: Fiscal year ending late Aug / early Sep | C5: FY2021 | D5: FY2022 | E5: FY2023 | F5: FY2024 | G5: FY2025 | H5: Source note
B6: INCOME STATEMENT
B7: Net sales | C7: 192052 | D7: 222730 | E7: 237710 | F7: 249625 | G7: 269912 | H7: 10-K / earnings releases
B8: Membership fees | C8: 3877 | D8: 4224 | E8: 4580 | F8: 4828 | G8: 5323 | H8: 10-K / earnings releases
B9: Total revenue | C9: =C7+C8 -> 195929 | D9: =D7+D8 -> 226954 | E9: =E7+E8 -> 242290 | F9: =F7+F8 -> 254453 | G9: =G7+G8 -> 275235 | H9: Net sales + membership fees
B10: Merchandise costs (COGS) | C10: 170684 | D10: 199382 | E10: 212586 | F10: 222358 | G10: 239886 | H10: 10-K / earnings releases
B11: Selling, general & administrative | C11: 18537 | D11: 19779 | E11: 21590 | F11: 22810 | G11: 24966 | H11: 10-K / earnings releases
B12: Operating income | C12: =C9-C10-C11 -> 6708 | D12: =D9-D10-D11 -> 7793 | E12: =E9-E10-E11 -> 8114 | F12: =F9-F10-F11 -> 9285 | G12: =G9-G10-G11 -> 10383 | H12: Total revenue − COGS − SG&A
B13: Operating margin | C13: =C12/C9 -> 0.034236892 | D13: =D12/D9 -> 0.034337355 | E13: =E12/E9 -> 0.033488794 | F13: =F12/F9 -> 0.036490039 | G13: =G12/G9 -> 0.037724127 | H13: Operating income / total revenue
B14: Interest expense | C14: -171 | D14: -158 | E14: -160 | F14: -169 | G14: -154 | H14: 10-K / earnings releases
B15: Interest income & other, net | C15: 143 | D15: 205 | E15: 533 | F15: 624 | G15: 589 | H15: 10-K / earnings releases
B16: Pre-tax income | C16: =C12+C14+C15 -> 6680 | D16: =D12+D14+D15 -> 7840 | E16: =E12+E14+E15 -> 8487 | F16: =F12+F14+F15 -> 9740 | G16: =G12+G14+G15 -> 10818 | H16: Operating income + other inc/(exp)
B17: Provision for income taxes | C17: -1601 | D17: -1925 | E17: -2195 | F17: -2373 | G17: -2719 | H17: 10-K / earnings releases
B18: Effective tax rate | C18: =-C17/C16 -> 0.23967066 | D18: =-D17/D16 -> 0.24553571 | E18: =-E17/E16 -> 0.25863085 | F18: =-F17/F16 -> 0.2436345 | G18: =-G17/G16 -> 0.25134036 | H18: Taxes / pre-tax income
B19: Net income (consolidated) | C19: =C16+C17 -> 5079 | D19: =D16+D17 -> 5915 | E19: =E16+E17 -> 6292 | F19: =F16+F17 -> 7367 | G19: =G16+G17 -> 8099 | H19: Pre-tax income − taxes
B20: Less: noncontrolling interests | C20: -72 | D20: -71 | E20: 0 | F20: 0 | G20: 0 | H20: NCI (Taiwan JV bought out FY2022)
B21: Net income attributable to Costco | C21: =C19+C20 -> 5007 | D21: =D19+D20 -> 5844 | E21: =E19+E20 -> 6292 | F21: =F19+F20 -> 7367 | G21: =G19+G20 -> 8099 | H21: Consolidated − NCI
B22: Diluted EPS ($) | C22: 11.27 | D22: 13.14 | E22: 14.16 | F22: 16.56 | G22: 18.21 | H22: As reported
B23: Diluted shares (millions) | C23: 444.3 | D23: 444.8 | E23: 444.4 | F23: 444.759 | G23: 444.803 | H23: Weighted-avg diluted shares
B25: CASH FLOW / CAPITAL
B26: Depreciation & amortization | C26: 1781 | D26: 1900 | E26: 2077 | F26: 2237 | G26: 2426 | H26: Cash flow statement
B27: Stock-based compensation | C27: 665 | D27: 724 | E27: 774 | F27: 818 | G27: 860 | H27: Cash flow statement
B28: Net cash from operations | C28: 8958 | D28: 7392 | E28: 11068 | F28: 11339 | G28: 13335 | H28: Cash flow statement
B29: Capital expenditures | C29: 3588 | D29: 3891 | E29: 4323 | F29: 4710 | G29: 5498 | H29: Additions to property & equipment
B30: Free cash flow (levered) = CFO − capex | C30: =C28-C29 -> 5370 | D30: =D28-D29 -> 3501 | E30: =E28-E29 -> 6745 | F30: =F28-F29 -> 6629 | G30: =G28-G29 -> 7837 | H30: Operating cash flow − capex
B32: BALANCE SHEET (period-end)
B33: Cash & cash equivalents | C33: 11258 | D33: 10203 | E33: 13700 | F33: 9906 | G33: 14161 | H33: Balance sheet
B34: Short-term investments | C34: 917 | D34: 846 | E34: 1534 | F34: 1238 | G34: 1123 | H34: Balance sheet
B35: Cash + short-term investments | C35: =C33+C34 -> 12175 | D35: =D33+D34 -> 11049 | E35: =E33+E34 -> 15234 | F35: =F33+F34 -> 11144 | G35: =G33+G34 -> 15284 | H35: Liquidity
B36: Long-term debt (excl. current portion) | C36: 6692 | D36: 6484 | E36: 5377 | F36: 5794 | G36: 5713 | H36: Balance sheet
B37: Total Costco shareholders' equity | C37: 17564 | D37: 20642 | E37: 25058 | F37: 23622 | G37: 29164 | H37: Balance sheet
B39: Total revenue 4-yr CAGR (FY21→FY25) | C39: =(G9/C9)^(1/4)-1 -> 0.088682481

Sheet DCF Model
B2: COSTCO WHOLESALE — UNLEVERED DCF
B3: Unlevered free cash flow to firm · COGS & SG&A modeled separately · $ in millions except per-share
B5: Fiscal year | C5: FY2023A | D5: FY2024A | E5: FY2025A | F5: FY2026E | G5: FY2027E | H5: FY2028E | I5: FY2029E | J5: FY2030E
B6: Net sales | C6: =Historicals!E7 -> 237710 | D6: =Historicals!F7 -> 249625 | E6: =Historicals!G7 -> 269912 | F6: =E6*(1+Assumptions!C$19) -> 291504.96 | G6: =F6*(1+Assumptions!D$19) -> 313367.83 | H6: =G6*(1+Assumptions!E$19) -> 335303.58 | I6: =H6*(1+Assumptions!F$19) -> 357098.31 | J6: =I6*(1+Assumptions!G$19) -> 378524.21
B7: % growth | D7: =D6/C6-1 -> 0.050124101 | E7: =E6/D6-1 -> 0.081269905 | F7: =Assumptions!C$19 -> 0.08 | G7: =Assumptions!D$19 -> 0.075 | H7: =Assumptions!E$19 -> 0.07 | I7: =Assumptions!F$19 -> 0.065 | J7: =Assumptions!G$19 -> 0.06
B8: Membership fees | C8: =Historicals!E8 -> 4580 | D8: =Historicals!F8 -> 4828 | E8: =Historicals!G8 -> 5323 | F8: =E8*(1+Assumptions!C$20) -> 5775.455 | G8: =F8*(1+Assumptions!D$20) -> 6237.4914 | H8: =G8*(1+Assumptions!E$20) -> 6705.3033 | I8: =H8*(1+Assumptions!F$20) -> 7174.6745 | J8: =I8*(1+Assumptions!G$20) -> 7641.0283
B9: % growth | F9: =Assumptions!C$20 -> 0.085 | G9: =Assumptions!D$20 -> 0.08 | H9: =Assumptions!E$20 -> 0.075 | I9: =Assumptions!F$20 -> 0.07 | J9: =Assumptions!G$20 -> 0.065
B10: Total revenue | C10: =C6+C8 -> 242290 | D10: =D6+D8 -> 254453 | E10: =E6+E8 -> 275235 | F10: =F6+F8 -> 297280.41 | G10: =G6+G8 -> 319605.32 | H10: =H6+H8 -> 342008.88 | I10: =I6+I8 -> 364272.99 | J10: =J6+J8 -> 386165.24
B11: % growth | D11: =D10/C10-1 -> 0.050200173 | E11: =E10/D10-1 -> 0.081673236 | F11: =F10/E10-1 -> 0.080096699 | G11: =G10/F10-1 -> 0.075097138 | H11: =H10/G10-1 -> 0.070097581 | I11: =I10/H10-1 -> 0.065098028 | J11: =J10/I10-1 -> 0.060098479
B12: Less: merchandise costs (COGS) | C12: =-Historicals!E10 -> -212586 | D12: =-Historicals!F10 -> -222358 | E12: =-Historicals!G10 -> -239886 | F12: =-F6*Assumptions!C$21 -> -259002.16 | G12: =-G6*Assumptions!D$21 -> -278270.63 | H12: =-H6*Assumptions!E$21 -> -297581.93 | I12: =-I6*Assumptions!F$21 -> -316746.2 | J12: =-J6*Assumptions!G$21 -> -335561.71
B13: COGS % of net sales | C13: =-C12/C6 -> 0.89430819 | D13: =-D12/D6 -> 0.89076815 | E13: =-E12/E6 -> 0.88875634 | F13: =-F12/F6 -> 0.8885 | G13: =-G12/G6 -> 0.888 | H13: =-H12/H6 -> 0.8875 | I13: =-I12/I6 -> 0.887 | J13: =-J12/J6 -> 0.8865
B14: Less: SG&A | C14: =-Historicals!E11 -> -21590 | D14: =-Historicals!F11 -> -22810 | E14: =-Historicals!G11 -> -24966 | F14: =-F10*Assumptions!C$22 -> -26903.878 | G14: =-G10*Assumptions!D$22 -> -28892.321 | H14: =-H10*Assumptions!E$22 -> -30883.402 | I14: =-I10*Assumptions!F$22 -> -32857.423 | J14: =-J10*Assumptions!G$22 -> -34793.488
B15: SG&A % of total revenue | C15: =-C14/C10 -> 0.089108094 | D15: =-D14/D10 -> 0.089643274 | E15: =-E14/E10 -> 0.09070794 | F15: =-F14/F10 -> 0.0905 | G15: =-G14/G10 -> 0.0904 | H15: =-H14/H10 -> 0.0903 | I15: =-I14/I10 -> 0.0902 | J15: =-J14/J10 -> 0.0901
B16: Operating income (EBIT) | C16: =C10+C12+C14 -> 8114 | D16: =D10+D12+D14 -> 9285 | E16: =E10+E12+E14 -> 10383 | F16: =F10+F12+F14 -> 11374.38 | G16: =G10+G12+G14 -> 12442.367 | H16: =H10+H12+H14 -> 13543.554 | I16: =I10+I12+I14 -> 14669.36 | J16: =J10+J12+J14 -> 15810.038
B17: operating margin | C17: =C16/C10 -> 0.033488794 | D17: =D16/D10 -> 0.036490039 | E17: =E16/E10 -> 0.037724127 | F17: =F16/F10 -> 0.038261453 | G17: =G16/G10 -> 0.038930413 | H17: =H16/H10 -> 0.039600006 | I17: =I16/I10 -> 0.040270239 | J17: =J16/J10 -> 0.040941122
B18: Less: cash taxes on EBIT | F18: =-F16*Assumptions!$C28 -> -2843.5951 | G18: =-G16*Assumptions!$C28 -> -3110.5918 | H18: =-H16*Assumptions!$C28 -> -3385.8885 | I18: =-I16*Assumptions!$C28 -> -3667.3401 | J18: =-J16*Assumptions!$C28 -> -3952.5096
B19: NOPAT (EBIT after tax) | F19: =F16+F18 -> 8530.7854 | G19: =G16+G18 -> 9331.7755 | H19: =H16+H18 -> 10157.665 | I19: =I16+I18 -> 11002.02 | J19: =J16+J18 -> 11857.529
B20: Add: depreciation & amortization | F20: =F10*Assumptions!$C25 -> 2675.5237 | G20: =G10*Assumptions!$C25 -> 2876.4479 | H20: =H10*Assumptions!$C25 -> 3078.08 | I20: =I10*Assumptions!$C25 -> 3278.4569 | J20: =J10*Assumptions!$C25 -> 3475.4872
B21: Less: capital expenditures | F21: =-F10*Assumptions!$C26 -> -5945.6083 | G21: =-G10*Assumptions!$C26 -> -6392.1065 | H21: =-H10*Assumptions!$C26 -> -6840.1777 | I21: =-I10*Assumptions!$C26 -> -7285.4597 | J21: =-J10*Assumptions!$C26 -> -7723.3048
B22: Net working capital (memo) | E22: =E10*Assumptions!$C27 -> -8257.05 | F22: =F10*Assumptions!$C27 -> -8918.4124 | G22: =G10*Assumptions!$C27 -> -9588.1597 | H22: =H10*Assumptions!$C27 -> -10260.267 | I22: =I10*Assumptions!$C27 -> -10928.19 | J22: =J10*Assumptions!$C27 -> -11584.957
B23: Add: NWC change (source/(use) of cash) | F23: =E22-F22 -> 661.36245 | G23: =F22-G22 -> 669.74725 | H23: =G22-H22 -> 672.1068 | I23: =H22-I22 -> 667.92312 | J23: =I22-J22 -> 656.76758
B24: Unlevered free cash flow | F24: =F19+F20+F21+F23 -> 5922.0632 | G24: =G19+G20+G21+G23 -> 6485.8642 | H24: =H19+H20+H21+H23 -> 7067.6745 | I24: =I19+I20+I21+I23 -> 7662.9405 | J24: =J19+J20+J21+J23 -> 8266.4786
B25: Discount period (years) | F25: 1 | G25: 2 | H25: 3 | I25: 4 | J25: 5
B26: Discount factor @ WACC | F26: =1/(1+WACC!$C23)^F25 -> 0.91851126 | G26: =1/(1+WACC!$C23)^G25 -> 0.84366294 | H26: =1/(1+WACC!$C23)^H25 -> 0.77491391 | I26: =1/(1+WACC!$C23)^I25 -> 0.71176715 | J26: =1/(1+WACC!$C23)^J25 -> 0.65376615
B27: PV of unlevered FCF | F27: =F24*F26 -> 5439.4818 | G27: =G24*G26 -> 5471.8833 | H27: =H24*H26 -> 5476.8393 | I27: =I24*I26 -> 5454.2294 | J27: =J24*J26 -> 5404.3439
B29: DCF VALUATION — PERPETUITY GROWTH METHOD
B30: Sum of PV of explicit FCF (FY26–FY30) | F30: =SUM(F27:J27) -> 27246.778
B31: Terminal growth rate (g) | F31: =Assumptions!C31 -> 0.03
B32: Terminal-year FCF × (1+g) | F32: =J24*(1+F31) -> 8514.473
B33: Terminal value (undiscounted) = FCF×(1+g)/(WACC−g) | F33: =J24*(1+F31)/(WACC!$C23-F31) -> 145005.49
B34: PV of terminal value | F34: =F33*J26 -> 94799.682
B35: Enterprise value | F35: =F30+F34 -> 122046.46
B36: % of EV from terminal value | F36: =F34/F35 -> 0.77675078
B37: Add: net cash / (less: net debt) | F37: =Assumptions!C15 -> 9496
B38: Implied equity value | F38: =F35+F37 -> 131542.46
B39: Diluted shares (millions) | F39: =Assumptions!C8 -> 444.803
B40: Implied value per share | F40: =F38/F39 -> 295.73195
B41: Current share price | F41: =Assumptions!C7 -> 915
B42: Implied upside / (downside) | F42: =F40/F41-1 -> -0.67679568
B44: DCF VALUATION — EXIT EV/EBITDA MULTIPLE METHOD
...

Sheet Sensitivity
B2: SENSITIVITY ANALYSIS
B3: Implied value per share ($). Each cell recomputes the full DCF for the given WACC / assumption pair.
B5: Table 1 — Perpetuity method: value/share vs. WACC (down) × terminal growth (across)
B6: WACC \ g | C6: 0.02 | D6: 0.025 | E6: 0.03 | F6: 0.035 | G6: 0.04
B7: 0.07 | C7: =(NPV($B7,'DCF Model'!$F$24:$J$24)+('DCF Model'!$J$24*(1+C$6)/($B7-C$6))/(1+$B7)^5+Assumptions!C15)/Assumptions!C8 -> 356.20293 | D7: =(NPV($B7,'DCF Model'!$F$24:$J$24)+('DCF Model'!$J$24*(1+D$6)/($B7-D$6))/(1+$B7)^5+Assumptions!C15)/Assumptions!C8 -> 387.70979 | E7: =(NPV($B7,'DCF Model'!$F$24:$J$24)+('DCF Model'!$J$24*(1+E$6)/($B7-E$6))/(1+$B7)^5+Assumptions!C15)/Assumptions!C8 -> 427.09338 | F7: =(NPV($B7,'DCF Model'!$F$24:$J$24)+('DCF Model'!$J$24*(1+F$6)/($B7-F$6))/(1+$B7)^5+Assumptions!C15)/Assumptions!C8 -> 477.72941 | G7: =(NPV($B7,'DCF Model'!$F$24:$J$24)+('DCF Model'!$J$24*(1+G$6)/($B7-G$6))/(1+$B7)^5+Assumptions!C15)/Assumptions!C8 -> 545.24413
B8: 0.078 | C8: =(NPV($B8,'DCF Model'!$F$24:$J$24)+('DCF Model'!$J$24*(1+C$6)/($B8-C$6))/(1+$B8)^5+Assumptions!C15)/Assumptions!C8 -> 308.96181 | D8: =(NPV($B8,'DCF Model'!$F$24:$J$24)+('DCF Model'!$J$24*(1+D$6)/($B8-D$6))/(1+$B8)^5+Assumptions!C15)/Assumptions!C8 -> 331.34614 | E8: =(NPV($B8,'DCF Model'!$F$24:$J$24)+('DCF Model'!$J$24*(1+E$6)/($B8-E$6))/(1+$B8)^5+Assumptions!C15)/Assumptions!C8 -> 358.39386 | F8: =(NPV($B8,'DCF Model'!$F$24:$J$24)+('DCF Model'!$J$24*(1+F$6)/($B8-F$6))/(1+$B8)^5+Assumptions!C15)/Assumptions!C8 -> 391.73175 | G8: =(NPV($B8,'DCF Model'!$F$24:$J$24)+('DCF Model'!$J$24*(1+G$6)/($B8-G$6))/(1+$B8)^5+Assumptions!C15)/Assumptions!C8 -> 433.84277
B9: 0.086 | C9: =(NPV($B9,'DCF Model'!$F$24:$J$24)+('DCF Model'!$J$24*(1+C$6)/($B9-C$6))/(1+$B9)^5+Assumptions!C15)/Assumptions!C8 -> 273.19969 | D9: =(NPV($B9,'DCF Model'!$F$24:$J$24)+('DCF Model'!$J$24*(1+D$6)/($B9-D$6))/(1+$B9)^5+Assumptions!C15)/Assumptions!C8 -> 289.79288 | E9: =(NPV($B9,'DCF Model'!$F$24:$J$24)+('DCF Model'!$J$24*(1+E$6)/($B9-E$6))/(1+$B9)^5+Assumptions!C15)/Assumptions!C8 -> 309.34913 | F9: =(NPV($B9,'DCF Model'!$F$24:$J$24)+('DCF Model'!$J$24*(1+F$6)/($B9-F$6))/(1+$B9)^5+Assumptions!C15)/Assumptions!C8 -> 332.73995 | G9: =(NPV($B9,'DCF Model'!$F$24:$J$24)+('DCF Model'!$J$24*(1+G$6)/($B9-G$6))/(1+$B9)^5+Assumptions!C15)/Assumptions!C8 -> 361.21572
B10: 0.094 | C10: =(NPV($B10,'DCF Model'!$F$24:$J$24)+('DCF Model'!$J$24*(1+C$6)/($B10-C$6))/(1+$B10)^5+Assumptions!C15)/Assumptions!C8 -> 245.19275 | D10: =(NPV($B10,'DCF Model'!$F$24:$J$24)+('DCF Model'!$J$24*(1+D$6)/($B10-D$6))/(1+$B10)^5+Assumptions!C15)/Assumptions!C8 -> 257.8977 | E10: =(NPV($B10,'DCF Model'!$F$24:$J$24)+('DCF Model'!$J$24*(1+E$6)/($B10-E$6))/(1+$B10)^5+Assumptions!C15)/Assumptions!C8 -> 272.58779 | F10: =(NPV($B10,'DCF Model'!$F$24:$J$24)+('DCF Model'!$J$24*(1+F$6)/($B10-F$6))/(1+$B10)^5+Assumptions!C15)/Assumptions!C8 -> 289.76772 | G10: =(NPV($B10,'DCF Model'!$F$24:$J$24)+('DCF Model'!$J$24*(1+G$6)/($B10-G$6))/(1+$B10)^5+Assumptions!C15)/Assumptions!C8 -> 310.12913
B11: 0.102 | C11: =(NPV($B11,'DCF Model'!$F$24:$J$24)+('DCF Model'!$J$24*(1+C$6)/($B11-C$6))/(1+$B11)^5+Assumptions!C15)/Assumptions!C8 -> 222.67042 | D11: =(NPV($B11,'DCF Model'!$F$24:$J$24)+('DCF Model'!$J$24*(1+D$6)/($B11-D$6))/(1+$B11)^5+Assumptions!C15)/Assumptions!C8 -> 232.64953 | E11: =(NPV($B11,'DCF Model'!$F$24:$J$24)+('DCF Model'!$J$24*(1+E$6)/($B11-E$6))/(1+$B11)^5+Assumptions!C15)/Assumptions!C8 -> 244.01463 | F11: =(NPV($B11,'DCF Model'!$F$24:$J$24)+('DCF Model'!$J$24*(1+F$6)/($B11-F$6))/(1+$B11)^5+Assumptions!C15)/Assumptions!C8 -> 257.07601 | G11: =(NPV($B11,'DCF Model'!$F$24:$J$24)+('DCF Model'!$J$24*(1+G$6)/($B11-G$6))/(1+$B11)^5+Assumptions!C15)/Assumptions!C8 -> 272.24407
B12: Base case ≈ WACC 8.6% / g 3.0% (highlighted).
B14: Table 2 — Exit-multiple method: value/share vs. WACC (down) × EV/EBITDA (across)
B15: WACC \ exit x | C15: 14 | D15: 16 | E15: 18 | F15: 20 | G15: 22
B16: 0.07 | C16: =(NPV($B16,'DCF Model'!$F$24:$J$24)+(('DCF Model'!$J$16+'DCF Model'!$J$20)*C$15)/(1+$B16)^5+Assumptions!C15)/Assumptions!C8 -> 518.67739 | D16: =(NPV($B16,'DCF Model'!$F$24:$J$24)+(('DCF Model'!$J$16+'DCF Model'!$J$20)*D$15)/(1+$B16)^5+Assumptions!C15)/Assumptions!C8 -> 580.50392 | E16: =(NPV($B16,'DCF Model'!$F$24:$J$24)+(('DCF Model'!$J$16+'DCF Model'!$J$20)*E$15)/(1+$B16)^5+Assumptions!C15)/Assumptions!C8 -> 642.33045 | F16: =(NPV($B16,'DCF Model'!$F$24:$J$24)+(('DCF Model'!$J$16+'DCF Model'!$J$20)*F$15)/(1+$B16)^5+Assumptions!C15)/Assumptions!C8 -> 704.15698 | G16: =(NPV($B16,'DCF Model'!$F$24:$J$24)+(('DCF Model'!$J$16+'DCF Model'!$J$20)*G$15)/(1+$B16)^5+Assumptions!C15)/Assumptions!C8 -> 765.98351
B17: 0.078 | C17: =(NPV($B17,'DCF Model'!$F$24:$J$24)+(('DCF Model'!$J$16+'DCF Model'!$J$20)*C$15)/(1+$B17)^5+Assumptions!C15)/Assumptions!C8 -> 501.41759 | D17: =(NPV($B17,'DCF Model'!$F$24:$J$24)+(('DCF Model'!$J$16+'DCF Model'!$J$20)*D$15)/(1+$B17)^5+Assumptions!C15)/Assumptions!C8 -> 560.9838 | E17: =(NPV($B17,'DCF Model'!$F$24:$J$24)+(('DCF Model'!$J$16+'DCF Model'!$J$20)*E$15)/(1+$B17)^5+Assumptions!C15)/Assumptions!C8 -> 620.55001 | F17: =(NPV($B17,'DCF Model'!$F$24:$J$24)+(('DCF Model'!$J$16+'DCF Model'!$J$20)*F$15)/(1+$B17)^5+Assumptions!C15)/Assumptions!C8 -> 680.11622 | G17: =(NPV($B17,'DCF Model'!$F$24:$J$24)+(('DCF Model'!$J$16+'DCF Model'!$J$20)*G$15)/(1+$B17)^5+Assumptions!C15)/Assumptions!C8 -> 739.68242
B18: 0.086 | C18: =(NPV($B18,'DCF Model'!$F$24:$J$24)+(('DCF Model'!$J$16+'DCF Model'!$J$20)*C$15)/(1+$B18)^5+Assumptions!C15)/Assumptions!C8 -> 484.89592 | D18: =(NPV($B18,'DCF Model'!$F$24:$J$24)+(('DCF Model'!$J$16+'DCF Model'!$J$20)*D$15)/(1+$B18)^5+Assumptions!C15)/Assumptions!C8 -> 542.30024 | E18: =(NPV($B18,'DCF Model'!$F$24:$J$24)+(('DCF Model'!$J$16+'DCF Model'!$J$20)*E$15)/(1+$B18)^5+Assumptions!C15)/Assumptions!C8 -> 599.70457 | F18: =(NPV($B18,'DCF Model'!$F$24:$J$24)+(('DCF Model'!$J$16+'DCF Model'!$J$20)*F$15)/(1+$B18)^5+Assumptions!C15)/Assumptions!C8 -> 657.1089 | G18: =(NPV($B18,'DCF Model'!$F$24:$J$24)+(('DCF Model'!$J$16+'DCF Model'!$J$20)*G$15)/(1+$B18)^5+Assumptions!C15)/Assumptions!C8 -> 714.51323
B19: 0.094 | C19: =(NPV($B19,'DCF Model'!$F$24:$J$24)+(('DCF Model'!$J$16+'DCF Model'!$J$20)*C$15)/(1+$B19)^5+Assumptions!C15)/Assumptions!C8 -> 469.07548 | D19: =(NPV($B19,'DCF Model'!$F$24:$J$24)+(('DCF Model'!$J$16+'DCF Model'!$J$20)*D$15)/(1+$B19)^5+Assumptions!C15)/Assumptions!C8 -> 524.4114 | E19: =(NPV($B19,'DCF Model'!$F$24:$J$24)+(('DCF Model'!$J$16+'DCF Model'!$J$20)*E$15)/(1+$B19)^5+Assumptions!C15)/Assumptions!C8 -> 579.74733 | F19: =(NPV($B19,'DCF Model'!$F$24:$J$24)+(('DCF Model'!$J$16+'DCF Model'!$J$20)*F$15)/(1+$B19)^5+Assumptions!C15)/Assumptions!C8 -> 635.08325 | G19: =(NPV($B19,'DCF Model'!$F$24:$J$24)+(('DCF Model'!$J$16+'DCF Model'!$J$20)*G$15)/(1+$B19)^5+Assumptions!C15)/Assumptions!C8 -> 690.41917
B20: 0.102 | C20: =(NPV($B20,'DCF Model'!$F$24:$J$24)+(('DCF Model'!$J$16+'DCF Model'!$J$20)*C$15)/(1+$B20)^5+Assumptions!C15)/Assumptions!C8 -> 453.9215 | D20: =(NPV($B20,'DCF Model'!$F$24:$J$24)+(('DCF Model'!$J$16+'DCF Model'!$J$20)*D$15)/(1+$B20)^5+Assumptions!C15)/Assumptions!C8 -> 507.27781 | E20: =(NPV($B20,'DCF Model'!$F$24:$J$24)+(('DCF Model'!$J$16+'DCF Model'!$J$20)*E$15)/(1+$B20)^5+Assumptions!C15)/Assumptions!C8 -> 560.63412 | F20: =(NPV($B20,'DCF Model'!$F$24:$J$24)+(('DCF Model'!$J$16+'DCF Model'!$J$20)*F$15)/(1+$B20)^5+Assumptions!C15)/Assumptions!C8 -> 613.99043 | G20: =(NPV($B20,'DCF Model'!$F$24:$J$24)+(('DCF Model'!$J$16+'DCF Model'!$J$20)*G$15)/(1+$B20)^5+Assumptions!C15)/Assumptions!C8 -> 667.34674
B21: Base case ≈ WACC 8.6% / 18.0x exit (highlighted). COST currently trades ~30x EV/EBITDA.
B23: Valuation range summary (links to DCF Model)
B24: Value / share — perpetuity method | C24: ='DCF Model'!F40 -> 295.73195
B25: Value / share — exit-multiple method | C25: ='DCF Model'!F54 -> 592.82604
B26: Midpoint of the two methods | C26: =('DCF Model'!F40+'DCF Model'!F54)/2 -> 444.279
B27: Current share price | C27: =Assumptions!C7 -> 915
B28: The two DCF methods bracket a value below the current price; COST trades ~30x EV/EBITDA and ~46x P/E, so the market prices in materially more long-term growth than a 5-yr + terminal DCF.
